Workbook

Sheet Backlog
A1: Backlog de Requerimientos — Landing Pago por Negocio
A2: Elaborado a partir del bosquejo de requerimientos, la transcripción de la entrevista y las aclaraciones posteriores del cliente. Ver hoja 'Notas y Dudas'.
A4: ID | B4: Épica | C4: Rol / Actor | D4: Historia de Usuario | E4: Criterios de Aceptación | F4: Prioridad | G4: Estado | H4: Observaciones | I4: Estimación (SP) | J4: Sprint
A5: HU-001 | B5: Solicitud y Publicación de Eventos | C5: Cliente (Organizador) | D5: Como cliente organizador, quiero enviar una solicitud de evento al administrador indicando la fecha o fechas de duración del evento, descripción, mapa de la zona y ubicación, para pedir que mi evento se publique en la plataforma. | E5: - El formulario captura fecha o fechas de duración, descripción, ubicación y el mapa de la zona del evento. - Se permite indicar eventos de un solo día o de varios días. - La solicitud queda en estado 'pendiente' hasta revisión del admin. | F5: Alta | G5: Por definir | H5: El mapa de la zona lo entrega el propio cliente organizador; el admin no lo diseña (ver HU-042). La duración del evento debe quedar registrada para permitir entradas por día cuando corresponda. | I5: 3 | J5: Sprint 1
A6: HU-002 | B6: Solicitud y Publicación de Eventos | C6: Admin | D6: Como visitante, quiero hacer clic en un evento del carrusel para ver su detalle: descripción, categorías de entrada (General/VIP/Super VIP), precios, beneficios, horario, cronograma y fechas disponibles. | E6: - Se muestra descripción completa, categorías con precio y beneficios. - Se muestra el cronograma/horario del evento. - Se muestran las fechas disponibles cuando el evento dura varios días. - Existe un botón de compra visible. - Para eventos de varios días, el usuario puede identificar para qué día está comprando la entrada. | F6: Alta | G6: Por definir | I6: 3 | J6: Sprint 1
A7: HU-003 | B7: Solicitud y Publicación de Eventos | C7: Admin | D7: Como administrador, quiero crear/editar la landing page del evento aceptado (título, foto, servicios, tickets, cronograma, ubicación y fecha o fechas) para publicarlo. | E7: - Se pueden editar todos los campos. - Se pueden registrar una o varias fechas de duración del evento. - Los cambios se reflejan en la landing pública al guardar. - Si el evento dura varios días, sus fechas quedan disponibles para configurar y vender entradas por día. | F7: Alta | G7: Por definir | H7: La información de fechas debe permitir diferenciar eventos de un día y eventos de varios días. | I7: 5 | J7: Sprint 1
A8: HU-004 | B8: Solicitud y Publicación de Eventos | C8: Cliente (Organizador) | D8: Como cliente organizador, quiero poder solicitar la creación de varios eventos para gestionar más de uno en la plataforma. | E8: - Puedo enviar más de una solicitud de evento con mi cuenta. | F8: Media | G8: Por definir | I8: 2 | J8: Sprint 1
A9: HU-005 | B9: Landing Page Pública | C9: Público | D9: Como visitante, quiero ver un carrusel con todos los eventos disponibles para explorar las opciones. | E9: - El carrusel muestra los eventos publicados (activos). - Cada card muestra al menos título e imagen. | F9: Alta | G9: Por definir | I9: 3 | J9: Sprint 1
A10: HU-006 | B10: Landing Page Pública | C10: Público | D10: Como visitante, quiero hacer clic en un evento del carrusel para ver su detalle: descripción, categorías de entrada (General/VIP/Super VIP), precios, beneficios, horario y cronograma. | E10: - Se muestra descripción completa, categorías con precio y beneficios. - Se muestra el cronograma/horario del evento. - Existe un botón de compra visible. | F10: Alta | G10: Por definir | I10: 3 | J10: Sprint 1
A11: HU-007 | B11: Cuenta de Usuario | C11: Usuario Normal | D11: Como usuario, quiero crear una cuenta para poder iniciar sesión e inscribirme a eventos ya existentes comprando entradas (es obligatorio estar registrado para comprar). | E11: - Puedo registrarme con mis datos básicos. - No se puede comprar ninguna entrada sin haber iniciado sesión. | F11: Alta | G11: Por definir | H11: Confirmado: el login es obligatorio para inscribirse/comprar entradas a eventos existentes. | I11: 3 | J11: Sprint 1
A12: HU-008 | B12: Cuenta de Usuario | C12: Usuario Normal | D12: Como usuario, quiero recuperar mi contraseña olvidada para no perder el acceso a mi cuenta. | E12: - Puedo solicitar recuperación con mi correo registrado. - Recibo un enlace o código para restablecerla. | F12: Media | G12: Por definir | H12: No confirmado en el audio; validar con el cliente si se requiere para el MVP (marcado con 'X' en el bosquejo original). | I12: 2 | J12: Sprint 1
A13: HU-009 | B13: Cuenta de Usuario | C13: Usuario Normal | D13: Como administrador, quiero verificar los comprobantes de pago subidos por los usuarios y aprobar o rechazar la compra para confirmar que la transacción es real. | E13: - Veo la lista de compras pendientes de verificación con su comprobante. - Puedo aprobar o rechazar cada una. - Solo tras la aprobación se genera la entrada/QR del usuario. - La entrada aprobada conserva la fecha específica seleccionada, cuando corresponda. | F13: Baja | G13: Por definir | I13: 2 | J13: Sprint 1
A14: HU-010 | B14: Compra de Entradas | C14: Usuario Normal | D14: Como usuario, quiero comprar una entrada personal seleccionando la categoría (General/VIP/Super VIP) y, cuando el evento dure varios días, el día específico al que deseo asistir. | E14: - Selecciono categoría y cantidad. - Si el evento dura varios días, selecciono una fecha específica para cada entrada. - Veo precio, descuento y beneficios antes de confirmar. - La entrada queda asociada a la fecha seleccionada. | F14: Alta | G14: Por definir | H14: Nueva regla del cliente: en eventos de varios días se pueden comprar entradas para días específicos. | I14: 3 | J14: Sprint 2
A15: HU-011 | B15: Compra de Entradas | C15: Usuario Normal | D15: Como usuario, quiero comprar entradas para otras personas ingresando su correo, nombre y celular y, cuando el evento dure varios días, seleccionar el día específico para cada entrada, ya que cada entrada es independiente y queda asociada a esa persona. | E15: - Cada entrada comprada para un tercero requiere correo, nombre y celular. - En eventos de varios días, puedo seleccionar la fecha específica de cada entrada. - La entrada queda vinculada a esos datos y a la fecha seleccionada, no a mi cuenta. | F15: Media | G15: Por definir | H15: Cada entrada es independiente. La fecha seleccionada debe quedar registrada para validar el acceso correspondiente. | I15: 3 | J15: Sprint 2
A16: HU-012 | B16: Compra de Entradas | C16: Usuario Normal | D16: Como usuario, quiero subir el comprobante de pago (QR/transferencia) al comprar una entrada para que el administrador pueda verificar la transacción. | E16: - Puedo adjuntar una imagen del comprobante al finalizar la compra. - La compra queda en estado 'pendiente de verificación'. | F16: Alta | G16: Por definir | H16: El pago actual del sistema NO es pasarela automática: es transferencia por QR + comprobante subido manualmente. | I16: 3 | J16: Sprint 2
A17: HU-013 | B17: Compra de Entradas | C17: Admin | D17: Como administrador, quiero verificar los comprobantes de pago subidos por los usuarios y aprobar o rechazar la compra para confirmar que la transacción es real. | E17: - Veo la lista de compras pendientes de verificación con su comprobante. - Puedo aprobar o rechazar cada una. - Solo tras la aprobación se genera la entrada/QR del usuario. | F17: Alta | G17: Por definir | I17: 3 | J17: Sprint 2
A18: HU-014 | B18: Entrega y Vinculación de Manilla (QR) | C18: Admin / Sistema | D18: Como sistema, quiero generar un código QR imprimible (manilla) para cada entrada aprobada, incluyendo la fecha específica de la entrada cuando corresponda, para que el usuario pueda usarlo como identificación en el evento. | E18: - El QR se genera automáticamente al aprobar la compra. - El QR es único por entrada. - La entrada/QR queda asociado a la fecha específica seleccionada en eventos de varios días. | F18: Alta | G18: Por definir | H18: Aplica a ambos tipos de acceso (ver HU-054): el QR generado aquí se asigna automáticamente al perfil si el evento es QR Digital (HU-055), o se vincula en la entrega física si el evento es QR Físico (HU-015, HU-053). | I18: 3 | J18: Sprint 2
A19: HU-015 | B19: Entrega y Vinculación de Manilla (QR) | C19: Supervisor | D19: Como supervisor, quiero vincular la manilla física entregada en el evento con la cuenta del usuario, para asociar el QR físico a su cuenta digital. | E19: - Al entregar la manilla, el supervisor confirma la vinculación en el sistema. - A partir de ahí, toda interacción se hace mediante ese QR físico. | F19: Alta | G19: Por definir | H19: Confirmado: la vinculación del QR a la cuenta ocurre en el momento de la entrega física de la manilla, no en el registro en línea. Aplica únicamente cuando el evento está configurado como QR Físico/Manilla (ver HU-054). | I19: 3 | J19: Sprint 2
A20: HU-016 | B20: Control de Acceso al Evento | C20: Supervisor | D20: Como supervisor, quiero escanear la manilla/QR del usuario en la entrada para verificar que su acceso sea válido para la fecha del evento. | E20: - El escaneo valida que el QR corresponda a una entrada vigente. - Se verifica que la fecha de la entrada corresponda al día actual del evento. - Se muestra el estado (válido / ya usado / inválido). - Una entrada válida para un día específico no permite el acceso en una fecha distinta. | F20: Alta | G20: Por definir | H20: Nueva regla: las entradas de eventos de varios días pueden ser válidas únicamente para el día comprado. | I20: 3 | J20: Sprint 2
A21: HU-017 | B21: Control de Acceso al Evento | C21: Supervisor | D21: Como supervisor, quiero registrar los ingresos y salidas del usuario en la fecha correspondiente a su entrada (puede entrar y salir varias veces) para llevar el control de aforo en tiempo real. | E21: - Cada escaneo registra si es entrada o salida. - El usuario puede reingresar múltiples veces con el mismo QR durante la fecha para la que compró la entrada. - Los registros de acceso incluyen la fecha del evento para mantener la trazabilidad. | F21: Alta | G21: Por definir | H21: Confirmado: el ingreso/salida es repetible, no de un solo uso. | I21: 5 | J21: Sprint 2
A22: HU-018 | B22: Control de Acceso al Evento | C22: Supervisor | D22: Como supervisor, quiero ver el historial de personas a las que di ingreso para tener trazabilidad del control de acceso. | E22: - El historial registra fecha, hora y usuario ingresado/salido. | F22: Media | G22: Por definir | H22: El bosquejo original mencionaba también una foto del momento del ingreso; esto NO se confirmó en el audio. Validar con el cliente si aplica. | I22: 2 | J22: Sprint 3
A23: HU-019 | B23: Recarga de Saldo | C23: Recargador | D23: Como recargador, quiero escanear la manilla del usuario, ver sus datos e ingresar un monto para cargarle puntos a su billetera virtual global, de modo que el mismo saldo pueda utilizarse en distintos eventos. | E23: - Al escanear se muestra la información del usuario. - Ingreso el monto pagado en efectivo y se le acreditan los mismos puntos (1 a 1), sin límite máximo. - El saldo de la billetera global del usuario se actualiza de inmediato. - El saldo no se crea ni se separa en una billetera independiente por evento. | F23: Alta | G23: Por definir | H23: Cambio solicitado por el cliente: existe una única billetera global por usuario, compartida entre sus distintos eventos. Las recargas y compras mantienen su trazabilidad por evento, pero el saldo es global. | I23: 5 | J23: Sprint 2
A24: HU-020 | B24: Recarga de Saldo | C24: Recargador | D24: Como recargador, quiero ver el historial de actividad de puntos (recargas y compras) que un usuario realizó dentro del evento en el que fui asignado, ya que mi visibilidad se limita a ese evento aunque el saldo del usuario sea global. | E24: - El historial solo muestra la actividad de puntos ocurrida en el evento asignado (recargas hechas por mí y compras del usuario en ese evento). - Incluye nombre del usuario, monto y fecha. - El historial identifica el evento de cada movimiento mostrado. - No permite consultar el saldo ni movimientos completos de otros eventos más allá de lo necesario para mostrar la actividad del evento asignado. | F24: Alta | G24: Por definir | H24: El saldo es global; la visibilidad del recargador continúa limitada al evento al que fue asignado. | I24: 3 | J24: Sprint 2
A25: HU-021 | B25: Recarga de Saldo | C25: Recargador | D25: Como recargador, quiero poder gestionar errores de recarga para corregir transacciones mal ingresadas. | E25: - Puedo identificar y reportar una recarga incorrecta. | F25: Media | G25: Por definir | H25: No se detalló en el audio el flujo de corrección; queda pendiente de definir con el cliente. Actualizado: el cliente pidió resolver estos problemas explícitamente; ver HU-047, que cubre la validación y el manejo de errores de recarga. | I25: 2 | J25: Sprint 3
A26: HU-022 | B26: Compras dentro del Evento (Negocios) | C26: Ayudante | D26: Como ayudante, quiero seleccionar el producto que el cliente desea comprar y escanear su manilla/QR para cobrarlo con sus puntos. | E26: - Selecciono el producto del catálogo del negocio. - Al escanear, se descuenta el monto del saldo de puntos del usuario. | F26: Alta | G26: Por definir | I26: 5 | J26: Sprint 2
A27: HU-023 | B27: Compras dentro del Evento (Negocios) | C27: Sistema | D27: Como sistema, quiero bloquear el cobro cuando el usuario no tiene saldo de puntos suficiente, para evitar transacciones sin fondos. | E27: - Si el saldo es menor al monto de la compra, la transacción no se procesa. - Se muestra un mensaje de saldo insuficiente al ayudante. | F27: Alta | G27: Por definir | H27: Confirmado: 'no tiene saldo no le cobra'. | I27: 3 | J27: Sprint 2
A28: HU-024 | B28: Compras dentro del Evento (Negocios) | C28: Ayudante | D28: Como ayudante, quiero ver el historial de ventas que realicé para llevar control de mi desempeño. | E28: - El historial muestra fecha, producto y monto de cada venta. | F28: Media | G28: Por definir | I28: 2 | J28: Sprint 2
A29: HU-025 | B29: Compras dentro del Evento (Negocios) | C29: Sistema | D29: Como sistema, quiero acreditar el dinero recaudado por las ventas de un negocio a la cuenta del Usuario Negocio (no directamente al ayudante) para centralizar el control financiero del negocio. | E29: - Toda venta hecha por un ayudante se refleja en el saldo/reportes del Usuario Negocio dueño del puesto. | F29: Alta | G29: Por definir | H29: Confirmado: el dinero recaudado va al usuario negocio, no al ayudante. | I29: 3 | J29: Sprint 2
A30: HU-026 | B30: Devolución de Saldo (Puntos) | C30: Devolución | D30: Como encargado de devoluciones, quiero escanear la manilla/QR del usuario para identificarlo antes de procesar la devolución de sus puntos de acuerdo con las reglas de retiro del saldo. | E30: - El escaneo identifica correctamente al usuario y su billetera global. - Se muestra el saldo disponible para devolución. | F30: Alta | G30: Por definir | I30: 2 | J30: Sprint 3
A31: HU-027 | B31: Devolución de Saldo (Puntos) | C31: Devolución | D31: Como encargado de devoluciones, quiero ver el saldo disponible de la billetera global del usuario para calcular el monto a devolver en efectivo. | E31: - Se muestra el saldo actual de la billetera global del usuario en tiempo real. - El monto mostrado corresponde al saldo que puede ser retirado según las condiciones vigentes. | F31: Alta | G31: Por definir | I31: 2 | J31: Sprint 3
A32: HU-028 | B32: Devolución de Saldo (Puntos) | C32: Devolución | D32: Como encargado de devoluciones, quiero devolver en efectivo el saldo restante de la billetera global del usuario, cuando corresponda, para que pueda retirar sus puntos. | E32: - Al confirmar la devolución, el saldo de la billetera global del usuario queda en cero. - Queda un registro de la devolución realizada. - La devolución respeta el plazo establecido en los términos y condiciones: el usuario dispone de hasta 30 días después de finalizar el evento para retirar su saldo sobrante. - Una vez vencido el plazo de 30 días sin retirar el saldo, este deja de estar disponible para el usuario. | F32: Alta | G32: Por definir | H32: Nueva regla del cliente: después de finalizar el evento, el usuario tiene 30 días para retirar el saldo sobrante. Si no lo retira dentro de ese plazo, pierde el saldo. La billetera es global y compartida entre eventos. | I32: 3 | J32: Sprint 3
A33: HU-029 | B33: Devolución de Saldo (Puntos) | C33: Devolución | D33: Como encargado de devoluciones, quiero ver el historial de devoluciones de puntos que realicé, limitado al evento que el administrador me asignó, para llevar control de los retiros efectuados. | E33: - El historial muestra usuario, monto y fecha de cada devolución. - Solo se muestran devoluciones del evento asignado. - Cada devolución queda asociada al evento en el que fue procesada, aunque la billetera del usuario sea global. | F33: Media | G33: Por definir | I33: 2 | J33: Sprint 3
A34: HU-030 | B34: Devolución de Saldo (Puntos) | C34: Devolución | D34: Como encargado de devoluciones, quiero subir un comprobante o foto al momento de la devolución para validar que el dinero se entregó a la persona correcta. | E34: - Puedo adjuntar una foto al registrar la devolución. | F34: Media | G34: Por definir | H34: El cliente planteó esta duda explícitamente pero indicó que no está seguro de cómo debe resolverse. Actualizado: se resuelve mostrando datos adicionales (foto de primer ingreso y movimientos recientes) al momento de la devolución; ver HU-048. | I34: 3 | J34: Sprint 3
A35: HU-031 | B35: Gestión de Negocio | C35: Usuario Negocio | D35: Como usuario negocio, quiero crear uno o varios negocios/puestos para ofrecer mis productos dentro del evento. | E35: - Puedo registrar más de un negocio bajo mi cuenta. | F35: Alta | G35: Por definir | I35: 3 | J35: Sprint 1
A36: HU-032 | B36: Gestión de Negocio | C36: Usuario Negocio | D36: Como usuario negocio, quiero configurar el catálogo de productos de cada negocio (qué voy a vender) para que los ayudantes puedan cobrarlos. | E36: - Puedo agregar, editar y eliminar productos con nombre y precio. | F36: Alta | G36: Por definir | I36: 3 | J36: Sprint 1
A37: HU-033 | B37: Gestión de Negocio | C37: Usuario Negocio | D37: Como usuario negocio, quiero crear ayudantes y asignarles un rol (por ejemplo, cajero) para que me apoyen en el punto de venta durante el evento. | E37: - Puedo registrar un nuevo ayudante con sus datos de acceso. - Puedo definir su rol/función dentro del negocio. | F37: Media | G37: Por definir | I37: 3 | J37: Sprint 1
A38: HU-034 | B38: Gestión de Negocio | C38: Usuario Negocio | D38: Como usuario negocio, quiero asignar cada ayudante a un negocio específico para delegar las ventas correspondientes. | E38: - Puedo asociar uno o más ayudantes a un negocio. | F38: Media | G38: Por definir | I38: 2 | J38: Sprint 1
A39: HU-035 | B39: Dashboards y Reportes | C39: Admin | D39: Como administrador, quiero un dashboard general de TODOS los eventos (ingresos al evento, salidas, reingresos, faltantes por ingresar, compras, recargas, devoluciones y saldos pendientes de retiro) para supervisar toda la plataforma. | E39: - Muestra datos consolidados de todos los eventos. - Permite ver quién recarga más, quién devuelve más, etc. - Permite identificar saldos pendientes de retiro y, cuando corresponda, los plazos de 30 días asociados al cierre de un evento. | F39: Alta | G39: Por definir | H39: Confirmado: el admin ve TODO, a diferencia del cliente organizador que solo ve su propio evento. El saldo de usuario es global, pero las operaciones se pueden consultar por evento. | I39: 5 | J39: Sprint 3
A40: HU-036 | B40: Dashboards y Reportes | C40: Cliente (Organizador) | D40: Como cliente organizador, quiero un dashboard general de MI propio evento (ventas totales, ganancias, recargas, compras y devoluciones) para monitorear su desempeño. | E40: - Muestra ventas y ganancias solo del evento que administro. - Las recargas, compras y devoluciones se muestran identificadas por ese evento. - No muestra el saldo global completo de los usuarios como si perteneciera exclusivamente al evento. | F40: Alta | G40: Por definir | I40: 3 | J40: Sprint 3
A41: HU-037 | B41: Dashboards y Reportes | C41: Usuario Negocio | D41: Como usuario negocio, quiero un dashboard con lo que sucede en mis propios negocios (qué se vende más, qué ayudante vende más) para monitorear mi desempeño. | E41: - Muestra ventas, productos más vendidos y desempeño por ayudante. - Solo incluye datos de mis negocios. | F41: Media | G41: Por definir | I41: 3 | J41: Sprint 3
...

Sheet Resumen
A1: Resumen del Backlog
A3: Historias por Épica
A4: Épica | B4: N° de Historias
A5: Solicitud y Publicación de Eventos | B5: =COUNTIF(Backlog!$B$5:$B$59,A5) -> 6
A6: Landing Page Pública | B6: =COUNTIF(Backlog!$B$5:$B$59,A6) -> 2
A7: Cuenta de Usuario | B7: =COUNTIF(Backlog!$B$5:$B$59,A7) -> 4
A8: Compra de Entradas | B8: =COUNTIF(Backlog!$B$5:$B$59,A8) -> 4
A9: Entrega y Vinculación de Manilla (QR) | B9: =COUNTIF(Backlog!$B$5:$B$59,A9) -> 4
A10: Control de Acceso al Evento | B10: =COUNTIF(Backlog!$B$5:$B$59,A10) -> 4
A11: Recarga de Saldo | B11: =COUNTIF(Backlog!$B$5:$B$59,A11) -> 4
A12: Compras dentro del Evento (Negocios) | B12: =COUNTIF(Backlog!$B$5:$B$59,A12) -> 4
A13: Devolución de Saldo (Puntos) | B13: =COUNTIF(Backlog!$B$5:$B$59,A13) -> 6
A14: Gestión de Negocio | B14: =COUNTIF(Backlog!$B$5:$B$59,A14) -> 5
A15: Dashboards y Reportes | B15: =COUNTIF(Backlog!$B$5:$B$59,A15) -> 7
A16: Gestión de Tickets y Categorías | B16: =COUNTIF(Backlog!$B$5:$B$59,A16) -> 2
... A18: Devolución de Entradas | B18: =COUNTIF(Backlog!$B$5:$B$59,A18) -> 1
A19: Total | B19: =SUM(B5:B18) -> 55
A21: Historias por Prioridad
A22: Prioridad | B22: N° de Historias
A23: Alta | B23: =COUNTIF(Backlog!$F$5:$F$59,A23) -> 34
A24: Media | B24: =COUNTIF(Backlog!$F$5:$F$59,A24) -> 16
A25: Baja | B25: =COUNTIF(Backlog!$F$5:$F$59,A25) -> 5
A28: Balance de Carga por Sprint
A29: Sprint | B29: N° de Historias | C29: Puntos (Estimación SP) | D29: Alta | E29: Media | F29: Baja
A30: Sprint 1 | B30: =COUNTIF(Backlog!$J$5:$J$59,A30) -> 21 | C30: =SUMIFS(Backlog!$I$5:$I$59,Backlog!$J$5:$J$59,A30) -> 58 | D30: =COUNTIFS(Backlog!$J$5:$J$59,A30,Backlog!$F$5:$F$59,"Alta") -> 12 | E30: =COUNTIFS(Backlog!$J$5:$J$59,A30,Backlog!$F$5:$F$59,"Media") -> 6 | F30: =COUNTIFS(Backlog!$J$5:$J$59,A30,Backlog!$F$5:$F$59,"Baja") -> 3
A31: Sprint 2 | B31: =COUNTIF(Backlog!$J$5:$J$59,A31) -> 18 | C31: =SUMIFS(Backlog!$I$5:$I$59,Backlog!$J$5:$J$59,A31) -> 61 | D31: =COUNTIFS(Backlog!$J$5:$J$59,A31,Backlog!$F$5:$F$59,"Alta") -> 15 | E31: =COUNTIFS(Backlog!$J$5:$J$59,A31,Backlog!$F$5:$F$59,"Media") -> 3 | F31: =COUNTIFS(Backlog!$J$5:$J$59,A31,Backlog!$F$5:$F$59,"Baja") -> 0
A32: Sprint 3 | B32: =COUNTIF(Backlog!$J$5:$J$59,A32) -> 16 | C32: =SUMIFS(Backlog!$I$5:$I$59,Backlog!$J$5:$J$59,A32) -> 44 | D32: =COUNTIFS(Backlog!$J$5:$J$59,A32,Backlog!$F$5:$F$59,"Alta") -> 7 | E32: =COUNTIFS(Backlog!$J$5:$J$59,A32,Backlog!$F$5:$F$59,"Media") -> 7 | F32: =COUNTIFS(Backlog!$J$5:$J$59,A32,Backlog!$F$5:$F$59,"Baja") -> 2
A33: Total | B33: =SUM(B30:B32) -> 55 | C33: =SUM(C30:C32) -> 163 | D33: =SUM(D30:D32) -> 34 | E33: =SUM(E30:E32) -> 16 | F33: =SUM(F30:F32) -> 5

Sheet Notas y Dudas
A1: Notas, Inconsistencias y Preguntas Abiertas
A3: Estado | B3: Tema | C3: Detalle
A4: Resuelto | B4: Rol 'Cliente' = organizador del evento | C4: Confirmado por el cliente: 'Cliente' es el organizador del evento. Los usuarios que se inscriben a eventos existentes (comprando entradas) son el 'Usuario Normal'. Ambos roles quedaron separados en el backlog.
A5: Resuelto | B5: Billetera global y plazo de retiro | C5: Cambio confirmado por el cliente: ya no existe una billetera independiente por evento. Cada usuario tiene una única billetera global, cuyo saldo puede utilizarse en distintos eventos. Nueva regla: después de finalizar un evento, el usuario dispone de 30 días para retirar el saldo sobrante; si no lo retira dentro de ese plazo, pierde el saldo. Pendiente de precisión funcional: definir cómo se aplica el plazo de 30 días cuando el mismo usuario participa en otro evento antes de que venza el plazo y cómo se determina exactamente qué saldo queda sujeto al cierre de cada evento.
A6: Resuelto | B6: Diseño del mapa del evento | C6: Confirmado: el admin NO diseña la ubicación del staff en el mapa. El cliente organizador es quien envía el mapa de la zona donde se realizará el evento (ya capturado en HU-001). HU-042 y HU-043 quedaron con prioridad baja y se recomienda fusionar HU-042 con HU-001 en el refinamiento.
A7: Resuelto | B7: Botón de reportes del organizador | C7: Confirmado: es un reporte de VENTAS (HU-039). Como idea futura (no confirmada como requerimiento actual), el cliente mencionó agregar un botón separado para reportar incidencias (HU-045).
A8: Pendiente | B8: Devolución de la entrada al evento | C8: El cliente confirmó que existen DOS tipos de devolución: la de puntos/saldo (ya definida, HU-026 a HU-029) y la devolución de la entrada al evento en sí. Sobre esta segunda el cliente no está seguro de cómo debe funcionar; queda como anotación pendiente (HU-044).
A9: Resuelto | B9: Comprobante/foto en la devolución de puntos | C9: Resuelto: el cliente pidió mostrar más datos al momento de la devolución para verificar identidad. Se agregó HU-048: al devolver, se muestra la foto de primer ingreso del usuario (ver HU-046), su nombre y sus últimos movimientos, para confirmar que la manilla no fue tomada por otra persona.
A10: Resuelto | B10: Gestión de errores de recarga | C10: Resuelto: el cliente pidió explícitamente solucionar los problemas al cargar puntos a una cuenta. Se agregó HU-047, que cubre validación de montos, reintentos ante fallos de escaneo/conexión y registro de recargas pendientes.
A11: Pendiente | B11: Recuperar contraseña e historial del mapa | C11: Elementos marcados con 'X' en el bosquejo original (HU-008, HU-043); no fueron confirmados ni descartados explícitamente por el cliente. Validar si entran en el alcance del MVP.
A12: Resuelto | B12: Entradas para días específicos | C12: Nuevo requerimiento confirmado por el cliente: si un evento tiene varios días de duración, se podrán comprar entradas para un día específico. La fecha seleccionada debe quedar asociada a la entrada y validarse al momento del acceso.
A13: Pendiente | B13: Aplicación del plazo de 30 días con billetera global | C13: La billetera es global y compartida entre eventos, pero el cliente indicó que después de finalizar un evento hay 30 días para retirar el saldo sobrante y luego se pierde. Falta confirmar cómo se comporta el plazo si el usuario utiliza la misma billetera en otro evento dentro de esos 30 días y cómo se identifica el saldo afectado por el cierre de un evento.
A14: Resuelto | B14: Foto de verificación en reingresos | C14: Nueva funcionalidad pedida por el cliente: se captura una foto del usuario en su primer ingreso y se vuelve a mostrar en cada salida o reingreso, para asegurar que la manilla no se pase a otra persona (HU-046).
... A20: Resuelto | B20: Tipo de acceso del evento: QR Digital vs QR Físico | C20: Dato confirmado por el cliente tras hablar con el Ing. Eynar: al crear un evento, el sistema debe pedir que se seleccione el tipo de acceso. QR Digital: el QR se asigna directamente al perfil del usuario al comprar/aprobar su entrada (HU-055). QR Físico (Manilla): el usuario debe recoger una manilla física; recién en ese momento se vincula el QR a su entrada (HU-015, HU-053). Se agregó HU-054 para la configuración de este tipo de acceso al crear el evento.

Sheet Planificación de Sprints
A1: Planificación de Sprints — Landing Pago por Negocio
A2: Distribución basada en una estimación de esfuerzo (Estimación SP, escala tipo Fibonacci simplificada: 1,2,3,5) asignada por complejidad, y en el orden de dependencia funcional del sistema (primero configuración y cuentas, luego el flujo de compra/acceso/consumo en el evento, y al final devoluciones y reportes que dependen de lo anterior).
A4: Sprint 1
A5: Objetivo: Configuración y cuentas — dejar la plataforma lista para publicar eventos: solicitud y publicación de eventos, tipo de acceso del evento (QR Digital / QR Físico), vista de solicitudes para el admin, landing pública, cuentas de usuario (incluido el perfil con billetera), categorías de tickets, fechas de eventos, mapa del evento, alta de negocios/ayudantes y el panel de administración de todos los eventos.
A6: ID | B6: Épica | C6: Historia de Usuario (resumen) | D6: Prioridad | E6: Estimación (SP) | F6: Rol / Actor
A7: HU-001 | B7: Solicitud y Publicación de Eventos | C7: Como cliente organizador, quiero enviar una solicitud de evento al administrador indicando la fecha o fechas de duración, descripción, mapa de la zona y ubicación para pedir que mi evento se publique. | D7: Alta | E7: 3 | F7: Cliente (Organizador)
A8: HU-002 | B8: Solicitud y Publicación de Eventos | C8: Como administrador, quiero revisar y aceptar o rechazar las solicitudes de evento enviadas por los clientes organizadores para controlar qué eventos se publican. | D8: Alta | E8: 3 | F8: Admin
A9: HU-003 | B9: Solicitud y Publicación de Eventos | C9: Como administrador, quiero crear/editar la landing page del evento aceptado (título, foto, servicios, tickets, cronograma, ubicación y fecha o fechas) para publicarlo. | D9: Alta | E9: 5 | F9: Admin
A10: HU-054 | B10: Solicitud y Publicación de Eventos | C10: Como administrador, quiero seleccionar el tipo de acceso del evento (QR Digital o QR Físico/Manilla) al momento de crearlo, para definir cómo se vinculará el QR a cada entrada. | D10: Alta | E10: 3 | F10: Admin
A11: HU-004 | B11: Solicitud y Publicación de Eventos | C11: Como cliente organizador, quiero poder solicitar la creación de varios eventos para gestionar más de uno en la plataforma. | D11: Media | E11: 2 | F11: Cliente (Organizador)
A12: HU-051 | B12: Solicitud y Publicación de Eventos | C12: Como administrador, quiero una vista con todas las solicitudes de evento enviadas por los clientes, con toda su información, para crear el evento a partir de esa solicitud sin pedir los datos de nuevo. | D12: Alta | E12: 3 | F12: Admin
A13: HU-005 | B13: Landing Page Pública | C13: Como visitante, quiero ver un carrusel con todos los eventos disponibles para explorar las opciones. | D13: Alta | E13: 3 | F13: Público
A14: HU-006 | B14: Landing Page Pública | C14: Como visitante, quiero ver el detalle del evento con descripción, categorías, precios, beneficios, horario, cronograma y fechas disponibles para comprar entradas. | D14: Alta | E14: 3 | F14: Público
A15: HU-007 | B15: Cuenta de Usuario | C15: Como usuario, quiero crear una cuenta para poder iniciar sesión e inscribirme a eventos ya existentes comprando entradas (es obligatorio estar registrado para comprar). | D15: Alta | E15: 3 | F15: Usuario Normal
A16: HU-008 | B16: Cuenta de Usuario | C16: Como usuario, quiero recuperar mi contraseña olvidada para no perder el acceso a mi cuenta. | D16: Media | E16: 2 | F16: Usuario Normal
A17: HU-009 | B17: Cuenta de Usuario | C17: Como usuario, quiero editar mi perfil para mantener mis datos actualizados. | D17: Baja | E17: 2 | F17: Usuario Normal
A18: HU-052 | B18: Cuenta de Usuario | C18: Como usuario, quiero ver mi perfil con todos mis datos personales y el saldo de mi billetera global en un solo lugar. | D18: Media | E18: 3 | F18: Usuario Normal
... A27: HU-050 | B27: Dashboards y Reportes | C27: Como administrador, quiero un panel de administración para gestionar TODOS los eventos de la plataforma (no solo un dashboard consolidado), para entrar a cada evento y administrarlo individualmente. | D27: Alta | E27: 5 | F27: Admin
A28: Total Sprint 1 | E28: =SUM(E7:E27) -> 58 | F28: =COUNTA(A7:A27)&" historias" -> 21 historias
A30: Sprint 2
A31: Objetivo: Flujo de compra, acceso y consumo en el evento — comprar entradas para fechas específicas cuando corresponda, verificar pagos, generar y asignar el QR según el tipo de acceso del evento (digital automático o físico mediante puntos de entrega), controlar el acceso por fecha con verificación fotográfica en reingresos, recargar saldo global resolviendo errores comunes, y realizar compras dentro del evento.
A32: ID | B32: Épica | C32: Historia de Usuario (resumen) | D32: Prioridad | E32: Estimación (SP) | F32: Rol / Actor
A33: HU-010 | B33: Compra de Entradas | C33: Como usuario, quiero comprar una entrada personal seleccionando la categoría y, en eventos de varios días, el día específico al que deseo asistir. | D33: Alta | E33: 3 | F33: Usuario Normal
A34: HU-011 | B34: Compra de Entradas | C34: Como usuario, quiero comprar entradas para otras personas y, en eventos de varios días, seleccionar el día específico para cada entrada. | D34: Media | E34: 3 | F34: Usuario Normal
A35: HU-012 | B35: Compra de Entradas | C35: Como usuario, quiero subir el comprobante de pago (QR/transferencia) al comprar una entrada para que el administrador pueda verificar la transacción. | D35: Alta | E35: 3 | F35: Usuario Normal
A36: HU-013 | B36: Compra de Entradas | C36: Como administrador, quiero verificar los comprobantes de pago y aprobar o rechazar la compra, conservando la fecha específica de la entrada cuando corresponda. | D36: Alta | E36: 3 | F36: Admin
A37: HU-014 | B37: Entrega y Vinculación de Manilla (QR) | C37: Como sistema, quiero generar un código QR único para cada entrada aprobada, asociado a su fecha específica cuando corresponda. | D37: Alta | E37: 3 | F37: Admin / Sistema
A38: HU-055 | B38: Entrega y Vinculación de Manilla (QR) | C38: Como sistema, quiero asignar automáticamente el QR al perfil del usuario al aprobarse su entrada, cuando el evento sea de tipo QR Digital, para que lo use de inmediato sin pasar por un punto físico. | D38: Alta | E38: 3 | F38: Sistema
A39: HU-015 | B39: Entrega y Vinculación de Manilla (QR) | C39: Como supervisor, quiero vincular la manilla física entregada en el evento con la cuenta del usuario, para asociar el QR físico a su cuenta digital. | D39: Alta | E39: 3 | F39: Supervisor
A40: HU-053 | B40: Entrega y Vinculación de Manilla (QR) | C40: Como supervisor, quiero entregar manillas físicas en distintos puntos de recogida y asignar cada manilla al cliente que la reclama, para que la entrega se realice en varios puntos físicos. | D40: Media | E40: 3 | F40: Supervisor
A41: HU-016 | B41: Control de Acceso al Evento | C41: Como supervisor, quiero escanear la manilla/QR del usuario para verificar que su acceso sea válido para la fecha del evento. | D41: Alta | E41: 3 | F41: Supervisor
A42: HU-017 | B42: Control de Acceso al Evento | C42: Como supervisor, quiero registrar los ingresos y salidas del usuario en la fecha correspondiente a su entrada para controlar el aforo en tiempo real. | D42: Alta | E42: 5 | F42: Supervisor
A43: HU-046 | B43: Control de Acceso al Evento | C43: Como sistema, quiero capturar una foto en el primer ingreso y volver a mostrarla en cada salida o reingreso, para que el supervisor verifique que la manilla no fue pasada a otra persona. | D43: Alta | E43: 5 | F43: Supervisor / Sistema
A44: HU-019 | B44: Recarga de Saldo | C44: Como recargador, quiero cargar puntos a la billetera virtual global del usuario para que el mismo saldo pueda utilizarse en distintos eventos. | D44: Alta | E44: 5 | F44: Recargador
... A50: HU-025 | B50: Compras dentro del Evento (Negocios) | C50: Como sistema, quiero acreditar el dinero recaudado por las ventas de un negocio a la cuenta del Usuario Negocio (no directamente al ayudante) para centralizar el control financiero del negocio. | D50: Alta | E50: 3 | F50: Sistema
A51: Total Sprint 2 | E51: =SUM(E33:E50) -> 61 | F51: =COUNTA(A33:A50)&" historias" -> 18 historias
A53: Sprint 3
A54: Objetivo: Cierre del evento, devoluciones y reportes — devolución de saldo global respetando el plazo de 30 días y validando la identidad del usuario, devolución de entradas, retiro de ganancias por negocio, e historiales/dashboards de todos los roles.
A55: ID | B55: Épica | C55: Historia de Usuario (resumen) | D55: Prioridad | E55: Estimación (SP) | F55: Rol / Actor
A56: HU-018 | B56: Control de Acceso al Evento | C56: Como supervisor, quiero ver el historial de personas a las que di ingreso para tener trazabilidad del control de acceso. | D56: Media | E56: 2 | F56: Supervisor
...

Sheet Mapa HU Sprint 1
A1: Mapa de Historias de Usuario del Sprint 1 — Dónde se desarrolla cada una
A2: Rutas relativas a la raíz del repositorio. FE = frontend/src/modules/ (las rutas que empiezan por components, utils, context o api están en frontend/src/). BE = backend/src/modules/ (las rutas que empiezan por common están en backend/src/). Estado según la revisión del código.
A4: ID | B4: Épica | C4: Rol / Actor | D4: Historia de Usuario (resumen) | E4: Estado | F4: Frontend (archivos) | G4: Backend (archivos) | H4: Base de datos (modelos) | I4: Observaciones
A5: HU-001 | B5: Solicitud y Publicación de Eventos | C5: Cliente (Organizador) | D5: Enviar solicitud de evento con fecha(s), descripción, ubicación y mapa de la zona. | E5: Completa | F5: FE/organizer/SolicitudFormPage.jsx utils/schedule.js utils/validation.js | G5: BE/events/events.controller.ts (POST solicitudes) events.service.ts (createSolicitud) event-schedule.ts dto/events.dto.ts common/storage/storage.service.ts (subida del mapa) | H5: SolicitudEvento MapaHistorial | I5: Mapa obligatorio (imagen o PDF). Estado inicial PENDIENTE. Soporta eventos de uno o varios días.
A6: HU-004 | B6: Solicitud y Publicación de Eventos | C6: Cliente (Organizador) | D6: Solicitar la creación de varios eventos con la misma cuenta. | E6: Completa | F6: FE/organizer/MisSolicitudesPage.jsx | G6: BE/events/events.service.ts (misSolicitudes) | H6: SolicitudEvento | I6: No hay límite de solicitudes por cuenta.
A7: HU-002 | B7: Solicitud y Publicación de Eventos | C7: Admin | D7: Revisar y aprobar o rechazar solicitudes (versión de la hoja Planificación de Sprints). | E7: Completa | F7: FE/admin/SolicitudesListPage.jsx admin/SolicitudDetailPage.jsx | G7: BE/events/events.service.ts (revisarSolicitud) common/mail/mail.service.ts (correo al organizador) | H7: SolicitudEvento (estado, observaciones) | I7: En la hoja Backlog esta HU describe el detalle público del evento (duplica HU-006). El código cubre ambas versiones.
A8: HU-051 | B8: Solicitud y Publicación de Eventos | C8: Admin | D8: Ver todas las solicitudes y crear el evento desde ellas con los datos precargados. | E8: Completa | F8: FE/admin/SolicitudesListPage.jsx admin/SolicitudDetailPage.jsx admin/EventoEditPage.jsx (precarga con ?solicitudId=) | G8: BE/events/events.service.ts (allSolicitudes, createEvento con solicitudId) | H8: SolicitudEvento (estado EVENTO_CREADO) Evento | I8: Al crear el evento la solicitud pasa a EVENTO_CREADO.
A9: HU-003 | B9: Solicitud y Publicación de Eventos | C9: Admin | D9: Crear y editar la landing del evento (título, foto, servicios, cronograma, ubicación, fechas). | E9: Completa | F9: FE/admin/EventoEditPage.jsx components/form/CronogramaEditor.jsx components/form/ListEditor.jsx | G9: BE/events/events.service.ts (createEvento, updateEvento, updateFoto, syncFechas) event-content.ts event-schedule.ts | H9: Evento FechaEvento | I9: Para publicar exige foto, al menos una categoría y el enlace de Google Maps.
A10: HU-054 | B10: Solicitud y Publicación de Eventos | C10: Admin | D10: Seleccionar el tipo de acceso del evento (QR Digital o QR Físico/Manilla). | E10: Completa | F10: FE/admin/EventoEditPage.jsx (sección Acceso) utils/labels.js | G10: BE/events/events.service.ts (createEvento) dto/events.dto.ts | H10: Evento.tipoAcceso enum TipoAcceso | I10: El código agrega una tercera opción, AMBOS, que el backlog no contempla.
A11: HU-005 | B11: Landing Page Pública | C11: Público | D11: Ver un carrusel con los eventos publicados. | E11: Completa | F11: FE/public/HomePage.jsx public/EventsPage.jsx components/EventCard.jsx | G11: BE/events/events.service.ts (publicList, GET eventos/public) | H11: Evento (estado PUBLICADO) | I11: Solo se listan eventos con estado PUBLICADO.
A12: HU-006 | B12: Landing Page Pública | C12: Público | D12: Ver el detalle del evento: descripción, categorías, precios, beneficios, horario, cronograma y fechas. | E12: Completa | F12: FE/public/EventDetailPage.jsx components/event/CronogramaView.jsx | G12: BE/events/events.service.ts (publicDetail, GET eventos/public/:id) | H12: Evento FechaEvento CategoriaEntrada CategoriaFecha | I12: El botón de compra es 'Ver entradas' / 'Inicia sesión para comprar'; la compra es del Sprint 2.
A13: HU-007 | B13: Cuenta de Usuario | C13: Usuario Normal | D13: Registrarse e iniciar sesión (obligatorio para comprar). | E13: Completa | F13: FE/auth/RegisterPage.jsx auth/LoginPage.jsx context/AuthContext.jsx components/layout/ProtectedRoute.jsx | G13: BE/auth/auth.service.ts (register, login) auth/jwt.strategy.ts common/guards/jwt-auth.guard.ts common/guards/roles.guard.ts | H13: Usuario UsuarioRol | I13: Registro público siempre como rol CLIENTE. Autenticación con JWT.
A14: HU-008 | B14: Cuenta de Usuario | C14: Usuario Normal | D14: Recuperar la contraseña olvidada. | E14: Completa | F14: FE/auth/ForgotPasswordPage.jsx auth/ResetPasswordPage.jsx | G14: BE/auth/auth.service.ts (forgotPassword, resetPassword) common/security/tokens.ts common/mail/mail.service.ts | H14: PasswordResetToken | I14: Token de un solo uso, guardado como hash SHA-256, con expiración de 60 minutos.
A15: HU-009 | B15: Cuenta de Usuario | C15: Usuario Normal | D15: Editar el perfil personal (según la hoja Planificación de Sprints). | E15: Completa | F15: FE/profile/ProfilePage.jsx | G15: BE/users/users.controller.ts users.service.ts (updateMe, updateFoto, removeFoto) dto/update-profile.dto.ts common/security/user-identity.ts | H15: Usuario | I15: En la hoja Backlog esta HU es 'verificar comprobantes' (duplica HU-013 del Sprint 2).
... A25: HU-050 | B25: Dashboards y Reportes | C25: Admin | D25: Panel de administración para gestionar todos los eventos. | E25: Completa | F25: FE/admin/AdminDashboardPage.jsx admin/EventosAdminPage.jsx admin/components/EventoDetalleModal.jsx components/layout/AdminLayout.jsx components/layout/AdminSidebar.jsx | G25: BE/events/events.service.ts (adminAll, adminDetail) events.controller.ts (GET eventos/admin/all) | H25: Evento | I25: Lista eventos de cualquier estado con organizador, fechas, categorías y tipo de acceso.
A27: Componentes transversales del Sprint 1
A28: Componente | D28: Archivos | G28: Función
A29: Base de datos | D29: backend/prisma/schema.prisma backend/prisma/migrations/ (6 migraciones) backend/prisma/seed.ts | G29: Esquema completo con Prisma y MySQL. La migración sprint1_fechas_evento_varios_dias soporta eventos de varios días. El seed crea usuarios de prueba para cada rol.
A30: Autenticación y autorización | D30: backend/src/modules/auth/ backend/src/common/guards/ backend/src/common/decorators/roles.decorator.ts frontend/src/context/AuthContext.jsx frontend/src/components/layout/ProtectedRoute.jsx | G30: JWT, guards de rol en el backend y rutas protegidas por rol en el frontend.
A31: Validación y seguridad | D31: backend/src/main.ts backend/src/app.module.ts backend/src/common/validation/validators.ts backend/src/config/env.validation.ts | G31: Helmet, CORS restringido, rate limiting, ValidationPipe estricto (whitelist), validación de variables de entorno.
A32: Servicios comunes | D32: backend/src/common/storage/storage.service.ts backend/src/common/mail/mail.service.ts | G32: Subida de archivos a Cloudinary validando su contenido real, y envío de correos por SMTP.
A33: Capa API del frontend | D33: frontend/src/api/axios.js frontend/src/api/*.api.js | G33: Cliente axios único con token JWT; un archivo por módulo con las llamadas al backend.
A34: Componentes reutilizables | D34: frontend/src/components/ (form, ui, layout, event) | G34: Field, Modal, ConfirmDialog, Toast, layouts y sidebars compartidos por las pantallas.
A35: Invitaciones por correo (extra) | D35: backend/src/modules/admin-users/ frontend/src/modules/admin/UsuariosPage.jsx frontend/src/modules/auth/AceptarInvitacionPage.jsx | G35: No está en el backlog: el admin invita por correo a admins, organizadores y jefes de negocio.

Sheet Mapa HU Sprint 2
A1: Mapa de Historias de Usuario del Sprint 2 — Separación por módulos de trabajo
A2: Las 18 historias del Sprint 2 (61 SP) agrupadas en 5 módulos de trabajo. Resumen, épica, rol, prioridad y SP provienen de la hoja 'Planificación de Sprints'; los criterios de aceptación y observaciones, de la hoja 'Backlog'. Las columnas Frontend / Backend / Base de datos quedan por completar cuando se revise el código del Sprint 2 (mismo formato que 'Mapa HU Sprint 1'). Estado "Por revisar" = aún sin verificar contra el código.
A4: Módulo | B4: ID | C4: Épica | D4: Rol / Actor | E4: Historia de Usuario (resumen) | F4: Prioridad | G4: SP | H4: Criterios de aceptación | I4: Estado | J4: Frontend (archivos) | K4: Backend (archivos) | L4: Base de datos (modelos) | M4: Observaciones
A5: A: Compra de Entradas y Verificación de Pagos | B5: HU-010 | C5: Compra de Entradas | D5: Usuario Normal | E5: Como usuario, quiero comprar una entrada personal seleccionando la categoría y, en eventos de varios días, el día específico al que deseo asistir. | F5: Alta | G5: 3 | H5: - Selecciono categoría y cantidad. - Si el evento dura varios días, selecciono una fecha específica para cada entrada. - Veo precio, descuento y beneficios antes de confirmar. - La entrada queda asociada a la fecha seleccionada. | I5: Por revisar | M5: Nueva regla del cliente: en eventos de varios días se pueden comprar entradas para días específicos.
A6: A: Compra de Entradas y Verificación de Pagos | B6: HU-011 | C6: Compra de Entradas | D6: Usuario Normal | E6: Como usuario, quiero comprar entradas para otras personas y, en eventos de varios días, seleccionar el día específico para cada entrada. | F6: Media | G6: 3 | H6: - Cada entrada comprada para un tercero requiere correo, nombre y celular. - En eventos de varios días, puedo seleccionar la fecha específica de cada entrada. - La entrada queda vinculada a esos datos y a la fecha seleccionada, no a mi cuenta. | I6: Por revisar | M6: Cada entrada es independiente. La fecha seleccionada debe quedar registrada para validar el acceso correspondiente.
A7: A: Compra de Entradas y Verificación de Pagos | B7: HU-012 | C7: Compra de Entradas | D7: Usuario Normal | E7: Como usuario, quiero subir el comprobante de pago (QR/transferencia) al comprar una entrada para que el administrador pueda verificar la transacción. | F7: Alta | G7: 3 | H7: - Puedo adjuntar una imagen del comprobante al finalizar la compra. - La compra queda en estado 'pendiente de verificación'. | I7: Por revisar | M7: El pago actual del sistema NO es pasarela automática: es transferencia por QR + comprobante subido manualmente.
A8: A: Compra de Entradas y Verificación de Pagos | B8: HU-013 | C8: Compra de Entradas | D8: Admin | E8: Como administrador, quiero verificar los comprobantes de pago y aprobar o rechazar la compra, conservando la fecha específica de la entrada cuando corresponda. | F8: Alta | G8: 3 | H8: - Veo la lista de compras pendientes de verificación con su comprobante. - Puedo aprobar o rechazar cada una. - Solo tras la aprobación se genera la entrada/QR del usuario. | I8: Por revisar
A9: B: Generación y Vinculación de QR / Manillas | B9: HU-014 | C9: Entrega y Vinculación de Manilla (QR) | D9: Admin / Sistema | E9: Como sistema, quiero generar un código QR único para cada entrada aprobada, asociado a su fecha específica cuando corresponda. | F9: Alta | G9: 3 | H9: - El QR se genera automáticamente al aprobar la compra. - El QR es único por entrada. - La entrada/QR queda asociado a la fecha específica seleccionada en eventos de varios días. | I9: Por revisar | M9: Aplica a ambos tipos de acceso (ver HU-054): el QR generado aquí se asigna automáticamente al perfil si el evento es QR Digital (HU-055), o se vincula en la entrega física si el evento es QR Físico (HU-015, HU-053).
A10: B: Generación y Vinculación de QR / Manillas | B10: HU-055 | C10: Entrega y Vinculación de Manilla (QR) | D10: Sistema | E10: Como sistema, quiero asignar automáticamente el QR al perfil del usuario al aprobarse su entrada, cuando el evento sea de tipo QR Digital, para que lo use de inmediato sin pasar por un punto físico. | F10: Alta | G10: 3 | H10: - Cuando el evento es de tipo QR Digital (ver HU-054), el QR generado en HU-014 se asigna directamente al perfil del usuario al aprobarse la entrada. - El usuario puede ver y usar su QR digital desde su perfil (ver HU-052) para moverse dentro del evento. - Para este tipo de evento no se requiere el paso de recogida de manilla física (HU-015 y HU-053 aplican solo a eventos con QR Físico). | I10: Por revisar | M10: Nuevo requerimiento confirmado por el cliente tras hablar con el Ing. Eynar: define el flujo de QR Digital como alternativa a la manilla física. Depende de HU-054 y HU-014.
A11: B: Generación y Vinculación de QR / Manillas | B11: HU-053 | C11: Entrega y Vinculación de Manilla (QR) | D11: Supervisor | E11: Como supervisor, quiero entregar manillas físicas en distintos puntos de recogida y asignar cada manilla al cliente que la reclama, para que la entrega se realice en varios puntos físicos. | F11: Media | G11: 3 | H11: - Se pueden definir uno o varios puntos físicos de entrega de manillas para un mismo evento. - En cada punto, el supervisor asignado puede vincular una manilla disponible a la cuenta del cliente que la reclama. - El sistema registra en qué punto y por cuál supervisor fue entregada cada manilla. - Una vez entregada, la manilla queda vinculada igual que en HU-015. | I11: Por revisar | M11: Nueva funcionalidad solicitada por el cliente: manillas físicas en diversos puntos, donde el supervisor asigna la manilla al cliente que la recoge físicamente. Extiende HU-015 a múltiples puntos de entrega. Aplica solo cuando el evento está configurado como QR Físico/Manilla (ver HU-054).
A12: B: Generación y Vinculación de QR / Manillas | B12: HU-015 | C12: Entrega y Vinculación de Manilla (QR) | D12: Supervisor | E12: Como supervisor, quiero vincular la manilla física entregada en el evento con la cuenta del usuario, para asociar el QR físico a su cuenta digital. | F12: Alta | G12: 3 | H12: - Al entregar la manilla, el supervisor confirma la vinculación en el sistema. - A partir de ahí, toda interacción se hace mediante ese QR físico. | I12: Por revisar | M12: Confirmado: la vinculación del QR a la cuenta ocurre en el momento de la entrega física de la manilla, no en el registro en línea. Aplica únicamente cuando el evento está configurado como QR Físico/Manilla (ver HU-054).
A13: C: Control de Acceso y Verificación Fotográfica | B13: HU-016 | C13: Control de Acceso al Evento | D13: Supervisor | E13: Como supervisor, quiero escanear la manilla/QR del usuario para verificar que su acceso sea válido para la fecha del evento. | F13: Alta | G13: 3 | H13: - El escaneo valida que el QR corresponda a una entrada vigente. - Se verifica que la fecha de la entrada corresponda al día actual del evento. - Se muestra el estado (válido / ya usado / inválido). - Una entrada válida para un día específico no permite el acceso en una fecha distinta. | I13: Por revisar | M13: Nueva regla: las entradas de eventos de varios días pueden ser válidas únicamente para el día comprado.
A14: C: Control de Acceso y Verificación Fotográfica | B14: HU-017 | C14: Control de Acceso al Evento | D14: Supervisor | E14: Como supervisor, quiero registrar los ingresos y salidas del usuario en la fecha correspondiente a su entrada para controlar el aforo en tiempo real. | F14: Alta | G14: 5 | H14: - Cada escaneo registra si es entrada o salida. - El usuario puede reingresar múltiples veces con el mismo QR durante la fecha para la que compró la entrada. - Los registros de acceso incluyen la fecha del evento para mantener la trazabilidad. | I14: Por revisar | M14: Confirmado: el ingreso/salida es repetible, no de un solo uso.
A15: C: Control de Acceso y Verificación Fotográfica | B15: HU-046 | C15: Control de Acceso al Evento | D15: Supervisor / Sistema | E15: Como sistema, quiero capturar una foto en el primer ingreso y volver a mostrarla en cada salida o reingreso, para que el supervisor verifique que la manilla no fue pasada a otra persona. | F15: Alta | G15: 5 | H15: - El sistema captura una foto del usuario en el primer ingreso registrado con su manilla/QR. - La foto capturada queda asociada a la entrada/manilla del usuario. - En cada salida o reingreso posterior, se muestra la foto original al supervisor junto con los datos del usuario. - El supervisor puede comparar la foto mostrada con la persona presente antes de autorizar el paso. | I15: Por revisar | M15: Nueva funcionalidad solicitada por el cliente para evitar que la manilla se preste o se pase a otra persona en reingresos. Depende de HU-016 y HU-017; su resultado se reutiliza en HU-048 (devolución).
A16: D: Recarga de Billetera Virtual Global | B16: HU-019 | C16: Recarga de Saldo | D16: Recargador | E16: Como recargador, quiero cargar puntos a la billetera virtual global del usuario para que el mismo saldo pueda utilizarse en distintos eventos. | F16: Alta | G16: 5 | H16: - Al escanear se muestra la información del usuario. - Ingreso el monto pagado en efectivo y se le acreditan los mismos puntos (1 a 1), sin límite máximo. - El saldo de la billetera global del usuario se actualiza de inmediato. - El saldo no se crea ni se separa en una billetera independiente por evento. | I16: Por revisar | M16: Cambio solicitado por el cliente: existe una única billetera global por usuario, compartida entre sus distintos eventos. Las recargas y compras mantienen su trazabilidad por evento, pero el saldo es global.
A17: D: Recarga de Billetera Virtual Global | B17: HU-020 | C17: Recarga de Saldo | D17: Recargador | E17: Como recargador, quiero ver el historial de puntos de un usuario dentro del evento al que fui asignado, aunque el saldo del usuario sea global. | F17: Alta | G17: 3 | H17: - El historial solo muestra la actividad de puntos ocurrida en el evento asignado (recargas hechas por mí y compras del usuario en ese evento). - Incluye nombre del usuario, monto y fecha. - El historial identifica el evento de cada movimiento mostrado. - No permite consultar el saldo ni movimientos completos de otros eventos más allá de lo necesario para mostrar la actividad del evento asignado. | I17: Por revisar | M17: El saldo es global; la visibilidad del recargador continúa limitada al evento al que fue asignado.
A18: D: Recarga de Billetera Virtual Global | B18: HU-047 | C18: Recarga de Saldo | D18: Recargador / Sistema | E18: Como recargador, quiero que el sistema me ayude a resolver los problemas más comunes al cargar puntos a una cuenta, para completar la recarga sin perder el dinero cobrado en efectivo. | F18: Alta | G18: 3 | H18: - El sistema valida el monto ingresado antes de confirmar la recarga. - Si el escaneo de la manilla falla, permite reintentar o buscar al usuario manualmente. - Si la recarga no se confirma por un error de conexión, la transacción queda marcada como pendiente en vez de perderse, y puede reintentarse. - Queda un registro disponible para reportar incidencias de recarga. | I18: Por revisar | M18: Resuelve la duda pendiente registrada en HU-021 sobre el manejo de errores de recarga; el cliente pidió explícitamente solucionar estos problemas.
A19: E: Consumo y Cobro en Puntos de Venta (Negocios) | B19: HU-022 | C19: Compras dentro del Evento (Negocios) | D19: Ayudante | E19: Como ayudante, quiero seleccionar el producto que el cliente desea comprar y escanear su manilla/QR para cobrarlo con sus puntos. | F19: Alta | G19: 5 | H19: - Selecciono el producto del catálogo del negocio. - Al escanear, se descuenta el monto del saldo de puntos del usuario. | I19: Por revisar
A20: E: Consumo y Cobro en Puntos de Venta (Negocios) | B20: HU-023 | C20: Compras dentro del Evento (Negocios) | D20: Sistema | E20: Como sistema, quiero bloquear el cobro cuando el usuario no tiene saldo de puntos suficiente, para evitar transacciones sin fondos. | F20: Alta | G20: 3 | H20: - Si el saldo es menor al monto de la compra, la transacción no se procesa. - Se muestra un mensaje de saldo insuficiente al ayudante. | I20: Por revisar | M20: Confirmado: 'no tiene saldo no le cobra'.
A21: E: Consumo y Cobro en Puntos de Venta (Negocios) | B21: HU-024 | C21: Compras dentro del Evento (Negocios) | D21: Ayudante | E21: Como ayudante, quiero ver el historial de ventas que realicé para llevar control de mi desempeño. | F21: Media | G21: 2 | H21: - El historial muestra fecha, producto y monto de cada venta. | I21: Por revisar
A22: E: Consumo y Cobro en Puntos de Venta (Negocios) | B22: HU-025 | C22: Compras dentro del Evento (Negocios) | D22: Sistema | E22: Como sistema, quiero acreditar el dinero recaudado por las ventas de un negocio a la cuenta del Usuario Negocio (no directamente al ayudante) para centralizar el control financiero del negocio. | F22: Alta | G22: 3 | H22: - Toda venta hecha por un ayudante se refleja en el saldo/reportes del Usuario Negocio dueño del puesto. | I22: Por revisar | M22: Confirmado: el dinero recaudado va al usuario negocio, no al ayudante.
A25: Resumen de carga de trabajo por módulo
A26: Módulo | B26: N° de HUs | C26: Story Points | D26: Propósito del módulo | I26: Roles principales
A27: A: Compra de Entradas y Verificación de Pagos | B27: =COUNTIF($A$5:$A$22,A27) -> 4 | C27: =SUMIF($A$5:$A$22,A27,$G$5:$G$22) -> 12 | D27: Gestionar la adquisición de tickets por parte del usuario y la validación administrativa del comprobante de pago. | I27: Usuario Normal, Admin
A28: B: Generación y Vinculación de QR / Manillas | B28: =COUNTIF($A$5:$A$22,A28) -> 4 | C28: =SUMIF($A$5:$A$22,A28,$G$5:$G$22) -> 12 | D28: Emitir los QR únicos y asociarlos al usuario, ya sea de forma digital (perfil) o con la entrega de la manilla física en el evento. | I28: Sistema, Admin, Supervisor
A29: C: Control de Acceso y Verificación Fotográfica | B29: =COUNTIF($A$5:$A$22,A29) -> 3 | C29: =SUMIF($A$5:$A$22,A29,$G$5:$G$22) -> 13 | D29: Garantizar el ingreso seguro: validación por fecha, control de ingresos/salidas y prevención de suplantación con foto del primer ingreso. | I29: Supervisor, Sistema
A30: D: Recarga de Billetera Virtual Global | B30: =COUNTIF($A$5:$A$22,A30) -> 3 | C30: =SUMIF($A$5:$A$22,A30,$G$5:$G$22) -> 11 | D30: Cargar puntos a la billetera única del usuario, consultar el historial del evento y resolver los fallos comunes de recarga. | I30: Recargador, Sistema
A31: E: Consumo y Cobro en Puntos de Venta (Negocios) | B31: =COUNTIF($A$5:$A$22,A31) -> 4 | C31: =SUMIF($A$5:$A$22,A31,$G$5:$G$22) -> 13 | D31: Procesar las ventas de los puestos escaneando la manilla/QR, bloquear cobros sin saldo y acreditar lo recaudado al Usuario Negocio. | I31: Ayudante, Sistema
A32: TOTAL SPRINT 2 | B32: =SUM(B27:B31) -> 18 | C32: =SUM(C27:C31) -> 61
A33: Total según hoja 'Planificación de Sprints' | B33: =COUNTA('Planificación de Sprints'!A33:A50) -> 18 | C33: ='Planificación de Sprints'!E51 -> 61
A34: Diferencia (debe ser 0) | B34: =B32-B33 -> 0 | C34: =C32-C33 -> 0
